2022-05-24 22:54:37 [scrapy.utils.log] INFO: Scrapy 2.6.1 started (bot: tutorial)
2022-05-24 22:54:37 [scrapy.utils.log] INFO: Versions: lxml 4.6.5.0, libxml2 2.9.5, cssselect 1.1.0, parsel 1.6.0, w3lib 1.22.0, Twisted 21.7.0, Python 3.7.0 (v3.7.0:1bf9cc5093, Jun 27 2018, 04:06:47) [MSC v.1914 32 bit (Intel)], pyOpenSSL 19.1.0 (OpenSSL 1.1.1h  22 Sep 2020), cryptography 3.2.1, Platform Windows-10-10.0.19041-SP0
2022-05-24 22:54:37 [scrapy.crawler] INFO: Overridden settings:
{'BOT_NAME': 'tutorial',
 'LOG_FILE': 'logs\\tutorial\\quotes\\6bd8d2d8db7111ecb92cc03c59e910aa.log',
 'NEWSPIDER_MODULE': 'tutorial.spiders',
 'ROBOTSTXT_OBEY': True,
 'SPIDER_MODULES': ['tutorial.spiders'],
 'USER_AGENT': 'Mozilla/5.0 (Windows NT 10.0; Win64; x64) AppleWebKit/537.36 '
               '(KHTML, like Gecko) Chrome/100.0.4896.127 Safari/537.36'}
2022-05-24 22:54:37 [scrapy.utils.log] DEBUG: Using reactor: twisted.internet.selectreactor.SelectReactor
2022-05-24 22:54:37 [scrapy.extensions.telnet] INFO: Telnet Password: 73208883af63e88f
2022-05-24 22:54:37 [scrapy.middleware] INFO: Enabled extensions:
['scrapy.extensions.corestats.CoreStats',
 'scrapy.extensions.telnet.TelnetConsole',
 'scrapy.extensions.logstats.LogStats',
 'tutorial.extensions.NotificationException']
2022-05-24 22:54:37 [scrapy.middleware] INFO: Enabled downloader middlewares:
['scrapy.downloadermiddlewares.robotstxt.RobotsTxtMiddleware',
 'scrapy.downloadermiddlewares.httpauth.HttpAuthMiddleware',
 'scrapy.downloadermiddlewares.downloadtimeout.DownloadTimeoutMiddleware',
 'scrapy.downloadermiddlewares.defaultheaders.DefaultHeadersMiddleware',
 'scrapy.downloadermiddlewares.useragent.UserAgentMiddleware',
 'scrapy.downloadermiddlewares.retry.RetryMiddleware',
 'scrapy.downloadermiddlewares.redirect.MetaRefreshMiddleware',
 'scrapy.downloadermiddlewares.httpcompression.HttpCompressionMiddleware',
 'scrapy.downloadermiddlewares.redirect.RedirectMiddleware',
 'scrapy.downloadermiddlewares.cookies.CookiesMiddleware',
 'scrapy.downloadermiddlewares.httpproxy.HttpProxyMiddleware',
 'scrapy.downloadermiddlewares.stats.DownloaderStats']
2022-05-24 22:54:38 [scrapy.middleware] INFO: Enabled spider middlewares:
['scrapy.spidermiddlewares.httperror.HttpErrorMiddleware',
 'scrapy.spidermiddlewares.offsite.OffsiteMiddleware',
 'scrapy.spidermiddlewares.referer.RefererMiddleware',
 'scrapy.spidermiddlewares.urllength.UrlLengthMiddleware',
 'scrapy.spidermiddlewares.depth.DepthMiddleware']
2022-05-24 22:54:38 [scrapy.middleware] INFO: Enabled item pipelines:
['tutorial.pipelines.TextPipeline']
2022-05-24 22:54:38 [scrapy.core.engine] INFO: Spider opened
2022-05-24 22:54:38 [scrapy.extensions.logstats] INFO: Crawled 0 pages (at 0 pages/min), scraped 0 items (at 0 items/min)
2022-05-24 22:54:38 [urllib3.connectionpool] DEBUG: Starting new HTTP connection (1): localhost:5000
2022-05-24 22:54:42 [scrapy.utils.signal] ERROR: Error caught on signal handler: <bound method NotificationException.spider_opened of <tutorial.extensions.NotificationException object at 0x059977D0>>
Traceback (most recent call last):
  File "c:\users\mingbotian\appdata\local\programs\python\python37-32\lib\site-packages\urllib3\connection.py", line 175, in _new_conn
    (self._dns_host, self.port), self.timeout, **extra_kw
  File "c:\users\mingbotian\appdata\local\programs\python\python37-32\lib\site-packages\urllib3\util\connection.py", line 95, in create_connection
    raise err
  File "c:\users\mingbotian\appdata\local\programs\python\python37-32\lib\site-packages\urllib3\util\connection.py", line 85, in create_connection
    sock.connect(sa)
ConnectionRefusedError: [WinError 10061] 由于目标计算机积极拒绝，无法连接。

During handling of the above exception, another exception occurred:

Traceback (most recent call last):
  File "c:\users\mingbotian\appdata\local\programs\python\python37-32\lib\site-packages\urllib3\connectionpool.py", line 710, in urlopen
    chunked=chunked,
  File "c:\users\mingbotian\appdata\local\programs\python\python37-32\lib\site-packages\urllib3\connectionpool.py", line 398, in _make_request
    conn.request(method, url, **httplib_request_kw)
  File "c:\users\mingbotian\appdata\local\programs\python\python37-32\lib\site-packages\urllib3\connection.py", line 239, in request
    super(HTTPConnection, self).request(method, url, body=body, headers=headers)
  File "c:\users\mingbotian\appdata\local\programs\python\python37-32\lib\http\client.py", line 1229, in request
    self._send_request(method, url, body, headers, encode_chunked)
  File "c:\users\mingbotian\appdata\local\programs\python\python37-32\lib\http\client.py", line 1275, in _send_request
    self.endheaders(body, encode_chunked=encode_chunked)
  File "c:\users\mingbotian\appdata\local\programs\python\python37-32\lib\http\client.py", line 1224, in endheaders
    self._send_output(message_body, encode_chunked=encode_chunked)
  File "c:\users\mingbotian\appdata\local\programs\python\python37-32\lib\http\client.py", line 1016, in _send_output
    self.send(msg)
  File "c:\users\mingbotian\appdata\local\programs\python\python37-32\lib\http\client.py", line 956, in send
    self.connect()
  File "c:\users\mingbotian\appdata\local\programs\python\python37-32\lib\site-packages\urllib3\connection.py", line 205, in connect
    conn = self._new_conn()
  File "c:\users\mingbotian\appdata\local\programs\python\python37-32\lib\site-packages\urllib3\connection.py", line 187, in _new_conn
    self, "Failed to establish a new connection: %s" % e
urllib3.exceptions.NewConnectionError: <urllib3.connection.HTTPConnection object at 0x060187B0>: Failed to establish a new connection: [WinError 10061] 由于目标计算机积极拒绝，无法连接。

During handling of the above exception, another exception occurred:

Traceback (most recent call last):
  File "c:\users\mingbotian\appdata\local\programs\python\python37-32\lib\site-packages\requests\adapters.py", line 449, in send
    timeout=timeout
  File "c:\users\mingbotian\appdata\local\programs\python\python37-32\lib\site-packages\urllib3\connectionpool.py", line 786, in urlopen
    method, url, error=e, _pool=self, _stacktrace=sys.exc_info()[2]
  File "c:\users\mingbotian\appdata\local\programs\python\python37-32\lib\site-packages\urllib3\util\retry.py", line 592, in increment
    raise MaxRetryError(_pool, url, error or ResponseError(cause))
urllib3.exceptions.MaxRetryError: HTTPConnectionPool(host='localhost', port=5000): Max retries exceeded with url: /notify (Caused by NewConnectionError('<urllib3.connection.HTTPConnection object at 0x060187B0>: Failed to establish a new connection: [WinError 10061] 由于目标计算机积极拒绝，无法连接。'))

During handling of the above exception, another exception occurred:

Traceback (most recent call last):
  File "c:\users\mingbotian\appdata\local\programs\python\python37-32\lib\site-packages\scrapy\utils\defer.py", line 169, in maybeDeferred_coro
    result = f(*args, **kw)
  File "c:\users\mingbotian\appdata\local\programs\python\python37-32\lib\site-packages\pydispatch\robustapply.py", line 55, in robustApply
    return receiver(*arguments, **named)
  File "c:\users\mingbo~1\appdata\local\temp\4\tutorial-1653404043-kum8t2lx.egg\tutorial\extensions.py", line 25, in spider_opened
  File "c:\users\mingbotian\appdata\local\programs\python\python37-32\lib\site-packages\requests\api.py", line 119, in post
    return request('post', url, data=data, json=json, **kwargs)
  File "c:\users\mingbotian\appdata\local\programs\python\python37-32\lib\site-packages\requests\api.py", line 61, in request
    return session.request(method=method, url=url, **kwargs)
  File "c:\users\mingbotian\appdata\local\programs\python\python37-32\lib\site-packages\requests\sessions.py", line 542, in request
    resp = self.send(prep, **send_kwargs)
  File "c:\users\mingbotian\appdata\local\programs\python\python37-32\lib\site-packages\requests\sessions.py", line 655, in send
    r = adapter.send(request, **kwargs)
  File "c:\users\mingbotian\appdata\local\programs\python\python37-32\lib\site-packages\requests\adapters.py", line 516, in send
    raise ConnectionError(e, request=request)
requests.exceptions.ConnectionError: HTTPConnectionPool(host='localhost', port=5000): Max retries exceeded with url: /notify (Caused by NewConnectionError('<urllib3.connection.HTTPConnection object at 0x060187B0>: Failed to establish a new connection: [WinError 10061] 由于目标计算机积极拒绝，无法连接。'))
2022-05-24 22:54:42 [scrapy.extensions.telnet] INFO: Telnet console listening on 127.0.0.1:6023
2022-05-24 22:54:42 [scrapy.core.engine] DEBUG: Crawled (404) <GET http://quotes.toscrape.com/robots.txt> (referer: None)
2022-05-24 22:54:43 [scrapy.core.engine] DEBUG: Crawled (200) <GET http://quotes.toscrape.com/> (referer: None)
2022-05-24 22:54:43 [scrapy.core.scraper] DEBUG: Scraped from <200 http://quotes.toscrape.com/>
{'author': 'Albert Einstein',
 'tags': ['change', 'deep-thoughts', 'thinking', 'world'],
 'text': '“The world as we have created it is a process of o...'}
2022-05-24 22:54:43 [urllib3.connectionpool] DEBUG: Starting new HTTP connection (1): localhost:5000
2022-05-24 22:54:47 [scrapy.utils.signal] ERROR: Error caught on signal handler: <bound method NotificationException.item_scraped of <tutorial.extensions.NotificationException object at 0x059977D0>>
Traceback (most recent call last):
  File "c:\users\mingbotian\appdata\local\programs\python\python37-32\lib\site-packages\urllib3\connection.py", line 175, in _new_conn
    (self._dns_host, self.port), self.timeout, **extra_kw
  File "c:\users\mingbotian\appdata\local\programs\python\python37-32\lib\site-packages\urllib3\util\connection.py", line 95, in create_connection
    raise err
  File "c:\users\mingbotian\appdata\local\programs\python\python37-32\lib\site-packages\urllib3\util\connection.py", line 85, in create_connection
    sock.connect(sa)
ConnectionRefusedError: [WinError 10061] 由于目标计算机积极拒绝，无法连接。

During handling of the above exception, another exception occurred:

Traceback (most recent call last):
  File "c:\users\mingbotian\appdata\local\programs\python\python37-32\lib\site-packages\urllib3\connectionpool.py", line 710, in urlopen
    chunked=chunked,
  File "c:\users\mingbotian\appdata\local\programs\python\python37-32\lib\site-packages\urllib3\connectionpool.py", line 398, in _make_request
    conn.request(method, url, **httplib_request_kw)
  File "c:\users\mingbotian\appdata\local\programs\python\python37-32\lib\site-packages\urllib3\connection.py", line 239, in request
    super(HTTPConnection, self).request(method, url, body=body, headers=headers)
  File "c:\users\mingbotian\appdata\local\programs\python\python37-32\lib\http\client.py", line 1229, in request
    self._send_request(method, url, body, headers, encode_chunked)
  File "c:\users\mingbotian\appdata\local\programs\python\python37-32\lib\http\client.py", line 1275, in _send_request
    self.endheaders(body, encode_chunked=encode_chunked)
  File "c:\users\mingbotian\appdata\local\programs\python\python37-32\lib\http\client.py", line 1224, in endheaders
    self._send_output(message_body, encode_chunked=encode_chunked)
  File "c:\users\mingbotian\appdata\local\programs\python\python37-32\lib\http\client.py", line 1016, in _send_output
    self.send(msg)
  File "c:\users\mingbotian\appdata\local\programs\python\python37-32\lib\http\client.py", line 956, in send
    self.connect()
  File "c:\users\mingbotian\appdata\local\programs\python\python37-32\lib\site-packages\urllib3\connection.py", line 205, in connect
    conn = self._new_conn()
  File "c:\users\mingbotian\appdata\local\programs\python\python37-32\lib\site-packages\urllib3\connection.py", line 187, in _new_conn
    self, "Failed to establish a new connection: %s" % e
urllib3.exceptions.NewConnectionError: <urllib3.connection.HTTPConnection object at 0x060EC7F0>: Failed to establish a new connection: [WinError 10061] 由于目标计算机积极拒绝，无法连接。

During handling of the above exception, another exception occurred:

Traceback (most recent call last):
  File "c:\users\mingbotian\appdata\local\programs\python\python37-32\lib\site-packages\requests\adapters.py", line 449, in send
    timeout=timeout
  File "c:\users\mingbotian\appdata\local\programs\python\python37-32\lib\site-packages\urllib3\connectionpool.py", line 786, in urlopen
    method, url, error=e, _pool=self, _stacktrace=sys.exc_info()[2]
  File "c:\users\mingbotian\appdata\local\programs\python\python37-32\lib\site-packages\urllib3\util\retry.py", line 592, in increment
    raise MaxRetryError(_pool, url, error or ResponseError(cause))
urllib3.exceptions.MaxRetryError: HTTPConnectionPool(host='localhost', port=5000): Max retries exceeded with url: /notify (Caused by NewConnectionError('<urllib3.connection.HTTPConnection object at 0x060EC7F0>: Failed to establish a new connection: [WinError 10061] 由于目标计算机积极拒绝，无法连接。'))

During handling of the above exception, another exception occurred:

Traceback (most recent call last):
  File "c:\users\mingbotian\appdata\local\programs\python\python37-32\lib\site-packages\scrapy\utils\defer.py", line 169, in maybeDeferred_coro
    result = f(*args, **kw)
  File "c:\users\mingbotian\appdata\local\programs\python\python37-32\lib\site-packages\pydispatch\robustapply.py", line 55, in robustApply
    return receiver(*arguments, **named)
  File "c:\users\mingbo~1\appdata\local\temp\4\tutorial-1653404043-kum8t2lx.egg\tutorial\extensions.py", line 31, in item_scraped
  File "c:\users\mingbotian\appdata\local\programs\python\python37-32\lib\site-packages\requests\api.py", line 119, in post
    return request('post', url, data=data, json=json, **kwargs)
  File "c:\users\mingbotian\appdata\local\programs\python\python37-32\lib\site-packages\requests\api.py", line 61, in request
    return session.request(method=method, url=url, **kwargs)
  File "c:\users\mingbotian\appdata\local\programs\python\python37-32\lib\site-packages\requests\sessions.py", line 542, in request
    resp = self.send(prep, **send_kwargs)
  File "c:\users\mingbotian\appdata\local\programs\python\python37-32\lib\site-packages\requests\sessions.py", line 655, in send
    r = adapter.send(request, **kwargs)
  File "c:\users\mingbotian\appdata\local\programs\python\python37-32\lib\site-packages\requests\adapters.py", line 516, in send
    raise ConnectionError(e, request=request)
requests.exceptions.ConnectionError: HTTPConnectionPool(host='localhost', port=5000): Max retries exceeded with url: /notify (Caused by NewConnectionError('<urllib3.connection.HTTPConnection object at 0x060EC7F0>: Failed to establish a new connection: [WinError 10061] 由于目标计算机积极拒绝，无法连接。'))
2022-05-24 22:54:47 [scrapy.core.scraper] DEBUG: Scraped from <200 http://quotes.toscrape.com/>
{'author': 'J.K. Rowling',
 'tags': ['abilities', 'choices'],
 'text': '“It is our choices, Harry, that show what we truly...'}
2022-05-24 22:54:47 [urllib3.connectionpool] DEBUG: Starting new HTTP connection (1): localhost:5000
2022-05-24 22:54:51 [scrapy.utils.signal] ERROR: Error caught on signal handler: <bound method NotificationException.item_scraped of <tutorial.extensions.NotificationException object at 0x059977D0>>
Traceback (most recent call last):
  File "c:\users\mingbotian\appdata\local\programs\python\python37-32\lib\site-packages\urllib3\connection.py", line 175, in _new_conn
    (self._dns_host, self.port), self.timeout, **extra_kw
  File "c:\users\mingbotian\appdata\local\programs\python\python37-32\lib\site-packages\urllib3\util\connection.py", line 95, in create_connection
    raise err
  File "c:\users\mingbotian\appdata\local\programs\python\python37-32\lib\site-packages\urllib3\util\connection.py", line 85, in create_connection
    sock.connect(sa)
ConnectionRefusedError: [WinError 10061] 由于目标计算机积极拒绝，无法连接。

During handling of the above exception, another exception occurred:

Traceback (most recent call last):
  File "c:\users\mingbotian\appdata\local\programs\python\python37-32\lib\site-packages\urllib3\connectionpool.py", line 710, in urlopen
    chunked=chunked,
  File "c:\users\mingbotian\appdata\local\programs\python\python37-32\lib\site-packages\urllib3\connectionpool.py", line 398, in _make_request
    conn.request(method, url, **httplib_request_kw)
  File "c:\users\mingbotian\appdata\local\programs\python\python37-32\lib\site-packages\urllib3\connection.py", line 239, in request
    super(HTTPConnection, self).request(method, url, body=body, headers=headers)
  File "c:\users\mingbotian\appdata\local\programs\python\python37-32\lib\http\client.py", line 1229, in request
    self._send_request(method, url, body, headers, encode_chunked)
  File "c:\users\mingbotian\appdata\local\programs\python\python37-32\lib\http\client.py", line 1275, in _send_request
    self.endheaders(body, encode_chunked=encode_chunked)
  File "c:\users\mingbotian\appdata\local\programs\python\python37-32\lib\http\client.py", line 1224, in endheaders
    self._send_output(message_body, encode_chunked=encode_chunked)
  File "c:\users\mingbotian\appdata\local\programs\python\python37-32\lib\http\client.py", line 1016, in _send_output
    self.send(msg)
  File "c:\users\mingbotian\appdata\local\programs\python\python37-32\lib\http\client.py", line 956, in send
    self.connect()
  File "c:\users\mingbotian\appdata\local\programs\python\python37-32\lib\site-packages\urllib3\connection.py", line 205, in connect
    conn = self._new_conn()
  File "c:\users\mingbotian\appdata\local\programs\python\python37-32\lib\site-packages\urllib3\connection.py", line 187, in _new_conn
    self, "Failed to establish a new connection: %s" % e
urllib3.exceptions.NewConnectionError: <urllib3.connection.HTTPConnection object at 0x060ECCF0>: Failed to establish a new connection: [WinError 10061] 由于目标计算机积极拒绝，无法连接。

During handling of the above exception, another exception occurred:

Traceback (most recent call last):
  File "c:\users\mingbotian\appdata\local\programs\python\python37-32\lib\site-packages\requests\adapters.py", line 449, in send
    timeout=timeout
  File "c:\users\mingbotian\appdata\local\programs\python\python37-32\lib\site-packages\urllib3\connectionpool.py", line 786, in urlopen
    method, url, error=e, _pool=self, _stacktrace=sys.exc_info()[2]
  File "c:\users\mingbotian\appdata\local\programs\python\python37-32\lib\site-packages\urllib3\util\retry.py", line 592, in increment
    raise MaxRetryError(_pool, url, error or ResponseError(cause))
urllib3.exceptions.MaxRetryError: HTTPConnectionPool(host='localhost', port=5000): Max retries exceeded with url: /notify (Caused by NewConnectionError('<urllib3.connection.HTTPConnection object at 0x060ECCF0>: Failed to establish a new connection: [WinError 10061] 由于目标计算机积极拒绝，无法连接。'))

During handling of the above exception, another exception occurred:

Traceback (most recent call last):
  File "c:\users\mingbotian\appdata\local\programs\python\python37-32\lib\site-packages\scrapy\utils\defer.py", line 169, in maybeDeferred_coro
    result = f(*args, **kw)
  File "c:\users\mingbotian\appdata\local\programs\python\python37-32\lib\site-packages\pydispatch\robustapply.py", line 55, in robustApply
    return receiver(*arguments, **named)
  File "c:\users\mingbo~1\appdata\local\temp\4\tutorial-1653404043-kum8t2lx.egg\tutorial\extensions.py", line 31, in item_scraped
  File "c:\users\mingbotian\appdata\local\programs\python\python37-32\lib\site-packages\requests\api.py", line 119, in post
    return request('post', url, data=data, json=json, **kwargs)
  File "c:\users\mingbotian\appdata\local\programs\python\python37-32\lib\site-packages\requests\api.py", line 61, in request
    return session.request(method=method, url=url, **kwargs)
  File "c:\users\mingbotian\appdata\local\programs\python\python37-32\lib\site-packages\requests\sessions.py", line 542, in request
    resp = self.send(prep, **send_kwargs)
  File "c:\users\mingbotian\appdata\local\programs\python\python37-32\lib\site-packages\requests\sessions.py", line 655, in send
    r = adapter.send(request, **kwargs)
  File "c:\users\mingbotian\appdata\local\programs\python\python37-32\lib\site-packages\requests\adapters.py", line 516, in send
    raise ConnectionError(e, request=request)
requests.exceptions.ConnectionError: HTTPConnectionPool(host='localhost', port=5000): Max retries exceeded with url: /notify (Caused by NewConnectionError('<urllib3.connection.HTTPConnection object at 0x060ECCF0>: Failed to establish a new connection: [WinError 10061] 由于目标计算机积极拒绝，无法连接。'))
2022-05-24 22:54:51 [scrapy.core.scraper] DEBUG: Scraped from <200 http://quotes.toscrape.com/>
{'author': 'Albert Einstein',
 'tags': ['inspirational', 'life', 'live', 'miracle', 'miracles'],
 'text': '“There are only two ways to live your life. One is...'}
2022-05-24 22:54:51 [urllib3.connectionpool] DEBUG: Starting new HTTP connection (1): localhost:5000
2022-05-24 22:54:55 [scrapy.utils.signal] ERROR: Error caught on signal handler: <bound method NotificationException.item_scraped of <tutorial.extensions.NotificationException object at 0x059977D0>>
Traceback (most recent call last):
  File "c:\users\mingbotian\appdata\local\programs\python\python37-32\lib\site-packages\urllib3\connection.py", line 175, in _new_conn
    (self._dns_host, self.port), self.timeout, **extra_kw
  File "c:\users\mingbotian\appdata\local\programs\python\python37-32\lib\site-packages\urllib3\util\connection.py", line 95, in create_connection
    raise err
  File "c:\users\mingbotian\appdata\local\programs\python\python37-32\lib\site-packages\urllib3\util\connection.py", line 85, in create_connection
    sock.connect(sa)
ConnectionRefusedError: [WinError 10061] 由于目标计算机积极拒绝，无法连接。

During handling of the above exception, another exception occurred:

Traceback (most recent call last):
  File "c:\users\mingbotian\appdata\local\programs\python\python37-32\lib\site-packages\urllib3\connectionpool.py", line 710, in urlopen
    chunked=chunked,
  File "c:\users\mingbotian\appdata\local\programs\python\python37-32\lib\site-packages\urllib3\connectionpool.py", line 398, in _make_request
    conn.request(method, url, **httplib_request_kw)
  File "c:\users\mingbotian\appdata\local\programs\python\python37-32\lib\site-packages\urllib3\connection.py", line 239, in request
    super(HTTPConnection, self).request(method, url, body=body, headers=headers)
  File "c:\users\mingbotian\appdata\local\programs\python\python37-32\lib\http\client.py", line 1229, in request
    self._send_request(method, url, body, headers, encode_chunked)
  File "c:\users\mingbotian\appdata\local\programs\python\python37-32\lib\http\client.py", line 1275, in _send_request
    self.endheaders(body, encode_chunked=encode_chunked)
  File "c:\users\mingbotian\appdata\local\programs\python\python37-32\lib\http\client.py", line 1224, in endheaders
    self._send_output(message_body, encode_chunked=encode_chunked)
  File "c:\users\mingbotian\appdata\local\programs\python\python37-32\lib\http\client.py", line 1016, in _send_output
    self.send(msg)
  File "c:\users\mingbotian\appdata\local\programs\python\python37-32\lib\http\client.py", line 956, in send
    self.connect()
  File "c:\users\mingbotian\appdata\local\programs\python\python37-32\lib\site-packages\urllib3\connection.py", line 205, in connect
    conn = self._new_conn()
  File "c:\users\mingbotian\appdata\local\programs\python\python37-32\lib\site-packages\urllib3\connection.py", line 187, in _new_conn
    self, "Failed to establish a new connection: %s" % e
urllib3.exceptions.NewConnectionError: <urllib3.connection.HTTPConnection object at 0x060EC730>: Failed to establish a new connection: [WinError 10061] 由于目标计算机积极拒绝，无法连接。

During handling of the above exception, another exception occurred:

Traceback (most recent call last):
  File "c:\users\mingbotian\appdata\local\programs\python\python37-32\lib\site-packages\requests\adapters.py", line 449, in send
    timeout=timeout
  File "c:\users\mingbotian\appdata\local\programs\python\python37-32\lib\site-packages\urllib3\connectionpool.py", line 786, in urlopen
    method, url, error=e, _pool=self, _stacktrace=sys.exc_info()[2]
  File "c:\users\mingbotian\appdata\local\programs\python\python37-32\lib\site-packages\urllib3\util\retry.py", line 592, in increment
    raise MaxRetryError(_pool, url, error or ResponseError(cause))
urllib3.exceptions.MaxRetryError: HTTPConnectionPool(host='localhost', port=5000): Max retries exceeded with url: /notify (Caused by NewConnectionError('<urllib3.connection.HTTPConnection object at 0x060EC730>: Failed to establish a new connection: [WinError 10061] 由于目标计算机积极拒绝，无法连接。'))

During handling of the above exception, another exception occurred:

Traceback (most recent call last):
  File "c:\users\mingbotian\appdata\local\programs\python\python37-32\lib\site-packages\scrapy\utils\defer.py", line 169, in maybeDeferred_coro
    result = f(*args, **kw)
  File "c:\users\mingbotian\appdata\local\programs\python\python37-32\lib\site-packages\pydispatch\robustapply.py", line 55, in robustApply
    return receiver(*arguments, **named)
  File "c:\users\mingbo~1\appdata\local\temp\4\tutorial-1653404043-kum8t2lx.egg\tutorial\extensions.py", line 31, in item_scraped
  File "c:\users\mingbotian\appdata\local\programs\python\python37-32\lib\site-packages\requests\api.py", line 119, in post
    return request('post', url, data=data, json=json, **kwargs)
  File "c:\users\mingbotian\appdata\local\programs\python\python37-32\lib\site-packages\requests\api.py", line 61, in request
    return session.request(method=method, url=url, **kwargs)
  File "c:\users\mingbotian\appdata\local\programs\python\python37-32\lib\site-packages\requests\sessions.py", line 542, in request
    resp = self.send(prep, **send_kwargs)
  File "c:\users\mingbotian\appdata\local\programs\python\python37-32\lib\site-packages\requests\sessions.py", line 655, in send
    r = adapter.send(request, **kwargs)
  File "c:\users\mingbotian\appdata\local\programs\python\python37-32\lib\site-packages\requests\adapters.py", line 516, in send
    raise ConnectionError(e, request=request)
requests.exceptions.ConnectionError: HTTPConnectionPool(host='localhost', port=5000): Max retries exceeded with url: /notify (Caused by NewConnectionError('<urllib3.connection.HTTPConnection object at 0x060EC730>: Failed to establish a new connection: [WinError 10061] 由于目标计算机积极拒绝，无法连接。'))
2022-05-24 22:54:55 [scrapy.core.scraper] DEBUG: Scraped from <200 http://quotes.toscrape.com/>
{'author': 'Jane Austen',
 'tags': ['aliteracy', 'books', 'classic', 'humor'],
 'text': '“The person, be it gentleman or lady, who has not...'}
2022-05-24 22:54:55 [urllib3.connectionpool] DEBUG: Starting new HTTP connection (1): localhost:5000
2022-05-24 22:54:59 [scrapy.utils.signal] ERROR: Error caught on signal handler: <bound method NotificationException.item_scraped of <tutorial.extensions.NotificationException object at 0x059977D0>>
Traceback (most recent call last):
  File "c:\users\mingbotian\appdata\local\programs\python\python37-32\lib\site-packages\urllib3\connection.py", line 175, in _new_conn
    (self._dns_host, self.port), self.timeout, **extra_kw
  File "c:\users\mingbotian\appdata\local\programs\python\python37-32\lib\site-packages\urllib3\util\connection.py", line 95, in create_connection
    raise err
  File "c:\users\mingbotian\appdata\local\programs\python\python37-32\lib\site-packages\urllib3\util\connection.py", line 85, in create_connection
    sock.connect(sa)
ConnectionRefusedError: [WinError 10061] 由于目标计算机积极拒绝，无法连接。

During handling of the above exception, another exception occurred:

Traceback (most recent call last):
  File "c:\users\mingbotian\appdata\local\programs\python\python37-32\lib\site-packages\urllib3\connectionpool.py", line 710, in urlopen
    chunked=chunked,
  File "c:\users\mingbotian\appdata\local\programs\python\python37-32\lib\site-packages\urllib3\connectionpool.py", line 398, in _make_request
    conn.request(method, url, **httplib_request_kw)
  File "c:\users\mingbotian\appdata\local\programs\python\python37-32\lib\site-packages\urllib3\connection.py", line 239, in request
    super(HTTPConnection, self).request(method, url, body=body, headers=headers)
  File "c:\users\mingbotian\appdata\local\programs\python\python37-32\lib\http\client.py", line 1229, in request
    self._send_request(method, url, body, headers, encode_chunked)
  File "c:\users\mingbotian\appdata\local\programs\python\python37-32\lib\http\client.py", line 1275, in _send_request
    self.endheaders(body, encode_chunked=encode_chunked)
  File "c:\users\mingbotian\appdata\local\programs\python\python37-32\lib\http\client.py", line 1224, in endheaders
    self._send_output(message_body, encode_chunked=encode_chunked)
  File "c:\users\mingbotian\appdata\local\programs\python\python37-32\lib\http\client.py", line 1016, in _send_output
    self.send(msg)
  File "c:\users\mingbotian\appdata\local\programs\python\python37-32\lib\http\client.py", line 956, in send
    self.connect()
  File "c:\users\mingbotian\appdata\local\programs\python\python37-32\lib\site-packages\urllib3\connection.py", line 205, in connect
    conn = self._new_conn()
  File "c:\users\mingbotian\appdata\local\programs\python\python37-32\lib\site-packages\urllib3\connection.py", line 187, in _new_conn
    self, "Failed to establish a new connection: %s" % e
urllib3.exceptions.NewConnectionError: <urllib3.connection.HTTPConnection object at 0x065735D0>: Failed to establish a new connection: [WinError 10061] 由于目标计算机积极拒绝，无法连接。

During handling of the above exception, another exception occurred:

Traceback (most recent call last):
  File "c:\users\mingbotian\appdata\local\programs\python\python37-32\lib\site-packages\requests\adapters.py", line 449, in send
    timeout=timeout
  File "c:\users\mingbotian\appdata\local\programs\python\python37-32\lib\site-packages\urllib3\connectionpool.py", line 786, in urlopen
    method, url, error=e, _pool=self, _stacktrace=sys.exc_info()[2]
  File "c:\users\mingbotian\appdata\local\programs\python\python37-32\lib\site-packages\urllib3\util\retry.py", line 592, in increment
    raise MaxRetryError(_pool, url, error or ResponseError(cause))
urllib3.exceptions.MaxRetryError: HTTPConnectionPool(host='localhost', port=5000): Max retries exceeded with url: /notify (Caused by NewConnectionError('<urllib3.connection.HTTPConnection object at 0x065735D0>: Failed to establish a new connection: [WinError 10061] 由于目标计算机积极拒绝，无法连接。'))

During handling of the above exception, another exception occurred:

Traceback (most recent call last):
  File "c:\users\mingbotian\appdata\local\programs\python\python37-32\lib\site-packages\scrapy\utils\defer.py", line 169, in maybeDeferred_coro
    result = f(*args, **kw)
  File "c:\users\mingbotian\appdata\local\programs\python\python37-32\lib\site-packages\pydispatch\robustapply.py", line 55, in robustApply
    return receiver(*arguments, **named)
  File "c:\users\mingbo~1\appdata\local\temp\4\tutorial-1653404043-kum8t2lx.egg\tutorial\extensions.py", line 31, in item_scraped
  File "c:\users\mingbotian\appdata\local\programs\python\python37-32\lib\site-packages\requests\api.py", line 119, in post
    return request('post', url, data=data, json=json, **kwargs)
  File "c:\users\mingbotian\appdata\local\programs\python\python37-32\lib\site-packages\requests\api.py", line 61, in request
    return session.request(method=method, url=url, **kwargs)
  File "c:\users\mingbotian\appdata\local\programs\python\python37-32\lib\site-packages\requests\sessions.py", line 542, in request
    resp = self.send(prep, **send_kwargs)
  File "c:\users\mingbotian\appdata\local\programs\python\python37-32\lib\site-packages\requests\sessions.py", line 655, in send
    r = adapter.send(request, **kwargs)
  File "c:\users\mingbotian\appdata\local\programs\python\python37-32\lib\site-packages\requests\adapters.py", line 516, in send
    raise ConnectionError(e, request=request)
requests.exceptions.ConnectionError: HTTPConnectionPool(host='localhost', port=5000): Max retries exceeded with url: /notify (Caused by NewConnectionError('<urllib3.connection.HTTPConnection object at 0x065735D0>: Failed to establish a new connection: [WinError 10061] 由于目标计算机积极拒绝，无法连接。'))
2022-05-24 22:54:59 [scrapy.core.scraper] DEBUG: Scraped from <200 http://quotes.toscrape.com/>
{'author': 'Marilyn Monroe',
 'tags': ['be-yourself', 'inspirational'],
 'text': "“Imperfection is beauty, madness is genius and it'..."}
2022-05-24 22:54:59 [urllib3.connectionpool] DEBUG: Starting new HTTP connection (1): localhost:5000
2022-05-24 22:55:03 [scrapy.utils.signal] ERROR: Error caught on signal handler: <bound method NotificationException.item_scraped of <tutorial.extensions.NotificationException object at 0x059977D0>>
Traceback (most recent call last):
  File "c:\users\mingbotian\appdata\local\programs\python\python37-32\lib\site-packages\urllib3\connection.py", line 175, in _new_conn
    (self._dns_host, self.port), self.timeout, **extra_kw
  File "c:\users\mingbotian\appdata\local\programs\python\python37-32\lib\site-packages\urllib3\util\connection.py", line 95, in create_connection
    raise err
  File "c:\users\mingbotian\appdata\local\programs\python\python37-32\lib\site-packages\urllib3\util\connection.py", line 85, in create_connection
    sock.connect(sa)
ConnectionRefusedError: [WinError 10061] 由于目标计算机积极拒绝，无法连接。

During handling of the above exception, another exception occurred:

Traceback (most recent call last):
  File "c:\users\mingbotian\appdata\local\programs\python\python37-32\lib\site-packages\urllib3\connectionpool.py", line 710, in urlopen
    chunked=chunked,
  File "c:\users\mingbotian\appdata\local\programs\python\python37-32\lib\site-packages\urllib3\connectionpool.py", line 398, in _make_request
    conn.request(method, url, **httplib_request_kw)
  File "c:\users\mingbotian\appdata\local\programs\python\python37-32\lib\site-packages\urllib3\connection.py", line 239, in request
    super(HTTPConnection, self).request(method, url, body=body, headers=headers)
  File "c:\users\mingbotian\appdata\local\programs\python\python37-32\lib\http\client.py", line 1229, in request
    self._send_request(method, url, body, headers, encode_chunked)
  File "c:\users\mingbotian\appdata\local\programs\python\python37-32\lib\http\client.py", line 1275, in _send_request
    self.endheaders(body, encode_chunked=encode_chunked)
  File "c:\users\mingbotian\appdata\local\programs\python\python37-32\lib\http\client.py", line 1224, in endheaders
    self._send_output(message_body, encode_chunked=encode_chunked)
  File "c:\users\mingbotian\appdata\local\programs\python\python37-32\lib\http\client.py", line 1016, in _send_output
    self.send(msg)
  File "c:\users\mingbotian\appdata\local\programs\python\python37-32\lib\http\client.py", line 956, in send
    self.connect()
  File "c:\users\mingbotian\appdata\local\programs\python\python37-32\lib\site-packages\urllib3\connection.py", line 205, in connect
    conn = self._new_conn()
  File "c:\users\mingbotian\appdata\local\programs\python\python37-32\lib\site-packages\urllib3\connection.py", line 187, in _new_conn
    self, "Failed to establish a new connection: %s" % e
urllib3.exceptions.NewConnectionError: <urllib3.connection.HTTPConnection object at 0x06573B90>: Failed to establish a new connection: [WinError 10061] 由于目标计算机积极拒绝，无法连接。

During handling of the above exception, another exception occurred:

Traceback (most recent call last):
  File "c:\users\mingbotian\appdata\local\programs\python\python37-32\lib\site-packages\requests\adapters.py", line 449, in send
    timeout=timeout
  File "c:\users\mingbotian\appdata\local\programs\python\python37-32\lib\site-packages\urllib3\connectionpool.py", line 786, in urlopen
    method, url, error=e, _pool=self, _stacktrace=sys.exc_info()[2]
  File "c:\users\mingbotian\appdata\local\programs\python\python37-32\lib\site-packages\urllib3\util\retry.py", line 592, in increment
    raise MaxRetryError(_pool, url, error or ResponseError(cause))
urllib3.exceptions.MaxRetryError: HTTPConnectionPool(host='localhost', port=5000): Max retries exceeded with url: /notify (Caused by NewConnectionError('<urllib3.connection.HTTPConnection object at 0x06573B90>: Failed to establish a new connection: [WinError 10061] 由于目标计算机积极拒绝，无法连接。'))

During handling of the above exception, another exception occurred:

Traceback (most recent call last):
  File "c:\users\mingbotian\appdata\local\programs\python\python37-32\lib\site-packages\scrapy\utils\defer.py", line 169, in maybeDeferred_coro
    result = f(*args, **kw)
  File "c:\users\mingbotian\appdata\local\programs\python\python37-32\lib\site-packages\pydispatch\robustapply.py", line 55, in robustApply
    return receiver(*arguments, **named)
  File "c:\users\mingbo~1\appdata\local\temp\4\tutorial-1653404043-kum8t2lx.egg\tutorial\extensions.py", line 31, in item_scraped
  File "c:\users\mingbotian\appdata\local\programs\python\python37-32\lib\site-packages\requests\api.py", line 119, in post
    return request('post', url, data=data, json=json, **kwargs)
  File "c:\users\mingbotian\appdata\local\programs\python\python37-32\lib\site-packages\requests\api.py", line 61, in request
    return session.request(method=method, url=url, **kwargs)
  File "c:\users\mingbotian\appdata\local\programs\python\python37-32\lib\site-packages\requests\sessions.py", line 542, in request
    resp = self.send(prep, **send_kwargs)
  File "c:\users\mingbotian\appdata\local\programs\python\python37-32\lib\site-packages\requests\sessions.py", line 655, in send
    r = adapter.send(request, **kwargs)
  File "c:\users\mingbotian\appdata\local\programs\python\python37-32\lib\site-packages\requests\adapters.py", line 516, in send
    raise ConnectionError(e, request=request)
requests.exceptions.ConnectionError: HTTPConnectionPool(host='localhost', port=5000): Max retries exceeded with url: /notify (Caused by NewConnectionError('<urllib3.connection.HTTPConnection object at 0x06573B90>: Failed to establish a new connection: [WinError 10061] 由于目标计算机积极拒绝，无法连接。'))
2022-05-24 22:55:03 [scrapy.core.scraper] DEBUG: Scraped from <200 http://quotes.toscrape.com/>
{'author': 'Albert Einstein',
 'tags': ['adulthood', 'success', 'value'],
 'text': '“Try not to become a man of success. Rather become...'}
2022-05-24 22:55:03 [urllib3.connectionpool] DEBUG: Starting new HTTP connection (1): localhost:5000
2022-05-24 22:55:07 [scrapy.utils.signal] ERROR: Error caught on signal handler: <bound method NotificationException.item_scraped of <tutorial.extensions.NotificationException object at 0x059977D0>>
Traceback (most recent call last):
  File "c:\users\mingbotian\appdata\local\programs\python\python37-32\lib\site-packages\urllib3\connection.py", line 175, in _new_conn
    (self._dns_host, self.port), self.timeout, **extra_kw
  File "c:\users\mingbotian\appdata\local\programs\python\python37-32\lib\site-packages\urllib3\util\connection.py", line 95, in create_connection
    raise err
  File "c:\users\mingbotian\appdata\local\programs\python\python37-32\lib\site-packages\urllib3\util\connection.py", line 85, in create_connection
    sock.connect(sa)
ConnectionRefusedError: [WinError 10061] 由于目标计算机积极拒绝，无法连接。

During handling of the above exception, another exception occurred:

Traceback (most recent call last):
  File "c:\users\mingbotian\appdata\local\programs\python\python37-32\lib\site-packages\urllib3\connectionpool.py", line 710, in urlopen
    chunked=chunked,
  File "c:\users\mingbotian\appdata\local\programs\python\python37-32\lib\site-packages\urllib3\connectionpool.py", line 398, in _make_request
    conn.request(method, url, **httplib_request_kw)
  File "c:\users\mingbotian\appdata\local\programs\python\python37-32\lib\site-packages\urllib3\connection.py", line 239, in request
    super(HTTPConnection, self).request(method, url, body=body, headers=headers)
  File "c:\users\mingbotian\appdata\local\programs\python\python37-32\lib\http\client.py", line 1229, in request
    self._send_request(method, url, body, headers, encode_chunked)
  File "c:\users\mingbotian\appdata\local\programs\python\python37-32\lib\http\client.py", line 1275, in _send_request
    self.endheaders(body, encode_chunked=encode_chunked)
  File "c:\users\mingbotian\appdata\local\programs\python\python37-32\lib\http\client.py", line 1224, in endheaders
    self._send_output(message_body, encode_chunked=encode_chunked)
  File "c:\users\mingbotian\appdata\local\programs\python\python37-32\lib\http\client.py", line 1016, in _send_output
    self.send(msg)
  File "c:\users\mingbotian\appdata\local\programs\python\python37-32\lib\http\client.py", line 956, in send
    self.connect()
  File "c:\users\mingbotian\appdata\local\programs\python\python37-32\lib\site-packages\urllib3\connection.py", line 205, in connect
    conn = self._new_conn()
  File "c:\users\mingbotian\appdata\local\programs\python\python37-32\lib\site-packages\urllib3\connection.py", line 187, in _new_conn
    self, "Failed to establish a new connection: %s" % e
urllib3.exceptions.NewConnectionError: <urllib3.connection.HTTPConnection object at 0x060EC590>: Failed to establish a new connection: [WinError 10061] 由于目标计算机积极拒绝，无法连接。

During handling of the above exception, another exception occurred:

Traceback (most recent call last):
  File "c:\users\mingbotian\appdata\local\programs\python\python37-32\lib\site-packages\requests\adapters.py", line 449, in send
    timeout=timeout
  File "c:\users\mingbotian\appdata\local\programs\python\python37-32\lib\site-packages\urllib3\connectionpool.py", line 786, in urlopen
    method, url, error=e, _pool=self, _stacktrace=sys.exc_info()[2]
  File "c:\users\mingbotian\appdata\local\programs\python\python37-32\lib\site-packages\urllib3\util\retry.py", line 592, in increment
    raise MaxRetryError(_pool, url, error or ResponseError(cause))
urllib3.exceptions.MaxRetryError: HTTPConnectionPool(host='localhost', port=5000): Max retries exceeded with url: /notify (Caused by NewConnectionError('<urllib3.connection.HTTPConnection object at 0x060EC590>: Failed to establish a new connection: [WinError 10061] 由于目标计算机积极拒绝，无法连接。'))

During handling of the above exception, another exception occurred:

Traceback (most recent call last):
  File "c:\users\mingbotian\appdata\local\programs\python\python37-32\lib\site-packages\scrapy\utils\defer.py", line 169, in maybeDeferred_coro
    result = f(*args, **kw)
  File "c:\users\mingbotian\appdata\local\programs\python\python37-32\lib\site-packages\pydispatch\robustapply.py", line 55, in robustApply
    return receiver(*arguments, **named)
  File "c:\users\mingbo~1\appdata\local\temp\4\tutorial-1653404043-kum8t2lx.egg\tutorial\extensions.py", line 31, in item_scraped
  File "c:\users\mingbotian\appdata\local\programs\python\python37-32\lib\site-packages\requests\api.py", line 119, in post
    return request('post', url, data=data, json=json, **kwargs)
  File "c:\users\mingbotian\appdata\local\programs\python\python37-32\lib\site-packages\requests\api.py", line 61, in request
    return session.request(method=method, url=url, **kwargs)
  File "c:\users\mingbotian\appdata\local\programs\python\python37-32\lib\site-packages\requests\sessions.py", line 542, in request
    resp = self.send(prep, **send_kwargs)
  File "c:\users\mingbotian\appdata\local\programs\python\python37-32\lib\site-packages\requests\sessions.py", line 655, in send
    r = adapter.send(request, **kwargs)
  File "c:\users\mingbotian\appdata\local\programs\python\python37-32\lib\site-packages\requests\adapters.py", line 516, in send
    raise ConnectionError(e, request=request)
requests.exceptions.ConnectionError: HTTPConnectionPool(host='localhost', port=5000): Max retries exceeded with url: /notify (Caused by NewConnectionError('<urllib3.connection.HTTPConnection object at 0x060EC590>: Failed to establish a new connection: [WinError 10061] 由于目标计算机积极拒绝，无法连接。'))
2022-05-24 22:55:07 [scrapy.core.scraper] DEBUG: Scraped from <200 http://quotes.toscrape.com/>
{'author': 'André Gide',
 'tags': ['life', 'love'],
 'text': '“It is better to be hated for what you are than to...'}
2022-05-24 22:55:07 [urllib3.connectionpool] DEBUG: Starting new HTTP connection (1): localhost:5000
2022-05-24 22:55:12 [scrapy.utils.signal] ERROR: Error caught on signal handler: <bound method NotificationException.item_scraped of <tutorial.extensions.NotificationException object at 0x059977D0>>
Traceback (most recent call last):
  File "c:\users\mingbotian\appdata\local\programs\python\python37-32\lib\site-packages\urllib3\connection.py", line 175, in _new_conn
    (self._dns_host, self.port), self.timeout, **extra_kw
  File "c:\users\mingbotian\appdata\local\programs\python\python37-32\lib\site-packages\urllib3\util\connection.py", line 95, in create_connection
    raise err
  File "c:\users\mingbotian\appdata\local\programs\python\python37-32\lib\site-packages\urllib3\util\connection.py", line 85, in create_connection
    sock.connect(sa)
ConnectionRefusedError: [WinError 10061] 由于目标计算机积极拒绝，无法连接。

During handling of the above exception, another exception occurred:

Traceback (most recent call last):
  File "c:\users\mingbotian\appdata\local\programs\python\python37-32\lib\site-packages\urllib3\connectionpool.py", line 710, in urlopen
    chunked=chunked,
  File "c:\users\mingbotian\appdata\local\programs\python\python37-32\lib\site-packages\urllib3\connectionpool.py", line 398, in _make_request
    conn.request(method, url, **httplib_request_kw)
  File "c:\users\mingbotian\appdata\local\programs\python\python37-32\lib\site-packages\urllib3\connection.py", line 239, in request
    super(HTTPConnection, self).request(method, url, body=body, headers=headers)
  File "c:\users\mingbotian\appdata\local\programs\python\python37-32\lib\http\client.py", line 1229, in request
    self._send_request(method, url, body, headers, encode_chunked)
  File "c:\users\mingbotian\appdata\local\programs\python\python37-32\lib\http\client.py", line 1275, in _send_request
    self.endheaders(body, encode_chunked=encode_chunked)
  File "c:\users\mingbotian\appdata\local\programs\python\python37-32\lib\http\client.py", line 1224, in endheaders
    self._send_output(message_body, encode_chunked=encode_chunked)
  File "c:\users\mingbotian\appdata\local\programs\python\python37-32\lib\http\client.py", line 1016, in _send_output
    self.send(msg)
  File "c:\users\mingbotian\appdata\local\programs\python\python37-32\lib\http\client.py", line 956, in send
    self.connect()
  File "c:\users\mingbotian\appdata\local\programs\python\python37-32\lib\site-packages\urllib3\connection.py", line 205, in connect
    conn = self._new_conn()
  File "c:\users\mingbotian\appdata\local\programs\python\python37-32\lib\site-packages\urllib3\connection.py", line 187, in _new_conn
    self, "Failed to establish a new connection: %s" % e
urllib3.exceptions.NewConnectionError: <urllib3.connection.HTTPConnection object at 0x065735F0>: Failed to establish a new connection: [WinError 10061] 由于目标计算机积极拒绝，无法连接。

During handling of the above exception, another exception occurred:

Traceback (most recent call last):
  File "c:\users\mingbotian\appdata\local\programs\python\python37-32\lib\site-packages\requests\adapters.py", line 449, in send
    timeout=timeout
  File "c:\users\mingbotian\appdata\local\programs\python\python37-32\lib\site-packages\urllib3\connectionpool.py", line 786, in urlopen
    method, url, error=e, _pool=self, _stacktrace=sys.exc_info()[2]
  File "c:\users\mingbotian\appdata\local\programs\python\python37-32\lib\site-packages\urllib3\util\retry.py", line 592, in increment
    raise MaxRetryError(_pool, url, error or ResponseError(cause))
urllib3.exceptions.MaxRetryError: HTTPConnectionPool(host='localhost', port=5000): Max retries exceeded with url: /notify (Caused by NewConnectionError('<urllib3.connection.HTTPConnection object at 0x065735F0>: Failed to establish a new connection: [WinError 10061] 由于目标计算机积极拒绝，无法连接。'))

During handling of the above exception, another exception occurred:

Traceback (most recent call last):
  File "c:\users\mingbotian\appdata\local\programs\python\python37-32\lib\site-packages\scrapy\utils\defer.py", line 169, in maybeDeferred_coro
    result = f(*args, **kw)
  File "c:\users\mingbotian\appdata\local\programs\python\python37-32\lib\site-packages\pydispatch\robustapply.py", line 55, in robustApply
    return receiver(*arguments, **named)
  File "c:\users\mingbo~1\appdata\local\temp\4\tutorial-1653404043-kum8t2lx.egg\tutorial\extensions.py", line 31, in item_scraped
  File "c:\users\mingbotian\appdata\local\programs\python\python37-32\lib\site-packages\requests\api.py", line 119, in post
    return request('post', url, data=data, json=json, **kwargs)
  File "c:\users\mingbotian\appdata\local\programs\python\python37-32\lib\site-packages\requests\api.py", line 61, in request
    return session.request(method=method, url=url, **kwargs)
  File "c:\users\mingbotian\appdata\local\programs\python\python37-32\lib\site-packages\requests\sessions.py", line 542, in request
    resp = self.send(prep, **send_kwargs)
  File "c:\users\mingbotian\appdata\local\programs\python\python37-32\lib\site-packages\requests\sessions.py", line 655, in send
    r = adapter.send(request, **kwargs)
  File "c:\users\mingbotian\appdata\local\programs\python\python37-32\lib\site-packages\requests\adapters.py", line 516, in send
    raise ConnectionError(e, request=request)
requests.exceptions.ConnectionError: HTTPConnectionPool(host='localhost', port=5000): Max retries exceeded with url: /notify (Caused by NewConnectionError('<urllib3.connection.HTTPConnection object at 0x065735F0>: Failed to establish a new connection: [WinError 10061] 由于目标计算机积极拒绝，无法连接。'))
2022-05-24 22:55:12 [scrapy.core.scraper] DEBUG: Scraped from <200 http://quotes.toscrape.com/>
{'author': 'Thomas A. Edison',
 'tags': ['edison', 'failure', 'inspirational', 'paraphrased'],
 'text': "“I have not failed. I've just found 10,000 ways th..."}
2022-05-24 22:55:12 [urllib3.connectionpool] DEBUG: Starting new HTTP connection (1): localhost:5000
2022-05-24 22:55:16 [scrapy.utils.signal] ERROR: Error caught on signal handler: <bound method NotificationException.item_scraped of <tutorial.extensions.NotificationException object at 0x059977D0>>
Traceback (most recent call last):
  File "c:\users\mingbotian\appdata\local\programs\python\python37-32\lib\site-packages\urllib3\connection.py", line 175, in _new_conn
    (self._dns_host, self.port), self.timeout, **extra_kw
  File "c:\users\mingbotian\appdata\local\programs\python\python37-32\lib\site-packages\urllib3\util\connection.py", line 95, in create_connection
    raise err
  File "c:\users\mingbotian\appdata\local\programs\python\python37-32\lib\site-packages\urllib3\util\connection.py", line 85, in create_connection
    sock.connect(sa)
ConnectionRefusedError: [WinError 10061] 由于目标计算机积极拒绝，无法连接。

During handling of the above exception, another exception occurred:

Traceback (most recent call last):
  File "c:\users\mingbotian\appdata\local\programs\python\python37-32\lib\site-packages\urllib3\connectionpool.py", line 710, in urlopen
    chunked=chunked,
  File "c:\users\mingbotian\appdata\local\programs\python\python37-32\lib\site-packages\urllib3\connectionpool.py", line 398, in _make_request
    conn.request(method, url, **httplib_request_kw)
  File "c:\users\mingbotian\appdata\local\programs\python\python37-32\lib\site-packages\urllib3\connection.py", line 239, in request
    super(HTTPConnection, self).request(method, url, body=body, headers=headers)
  File "c:\users\mingbotian\appdata\local\programs\python\python37-32\lib\http\client.py", line 1229, in request
    self._send_request(method, url, body, headers, encode_chunked)
  File "c:\users\mingbotian\appdata\local\programs\python\python37-32\lib\http\client.py", line 1275, in _send_request
    self.endheaders(body, encode_chunked=encode_chunked)
  File "c:\users\mingbotian\appdata\local\programs\python\python37-32\lib\http\client.py", line 1224, in endheaders
    self._send_output(message_body, encode_chunked=encode_chunked)
  File "c:\users\mingbotian\appdata\local\programs\python\python37-32\lib\http\client.py", line 1016, in _send_output
    self.send(msg)
  File "c:\users\mingbotian\appdata\local\programs\python\python37-32\lib\http\client.py", line 956, in send
    self.connect()
  File "c:\users\mingbotian\appdata\local\programs\python\python37-32\lib\site-packages\urllib3\connection.py", line 205, in connect
    conn = self._new_conn()
  File "c:\users\mingbotian\appdata\local\programs\python\python37-32\lib\site-packages\urllib3\connection.py", line 187, in _new_conn
    self, "Failed to establish a new connection: %s" % e
urllib3.exceptions.NewConnectionError: <urllib3.connection.HTTPConnection object at 0x06585290>: Failed to establish a new connection: [WinError 10061] 由于目标计算机积极拒绝，无法连接。

During handling of the above exception, another exception occurred:

Traceback (most recent call last):
  File "c:\users\mingbotian\appdata\local\programs\python\python37-32\lib\site-packages\requests\adapters.py", line 449, in send
    timeout=timeout
  File "c:\users\mingbotian\appdata\local\programs\python\python37-32\lib\site-packages\urllib3\connectionpool.py", line 786, in urlopen
    method, url, error=e, _pool=self, _stacktrace=sys.exc_info()[2]
  File "c:\users\mingbotian\appdata\local\programs\python\python37-32\lib\site-packages\urllib3\util\retry.py", line 592, in increment
    raise MaxRetryError(_pool, url, error or ResponseError(cause))
urllib3.exceptions.MaxRetryError: HTTPConnectionPool(host='localhost', port=5000): Max retries exceeded with url: /notify (Caused by NewConnectionError('<urllib3.connection.HTTPConnection object at 0x06585290>: Failed to establish a new connection: [WinError 10061] 由于目标计算机积极拒绝，无法连接。'))

During handling of the above exception, another exception occurred:

Traceback (most recent call last):
  File "c:\users\mingbotian\appdata\local\programs\python\python37-32\lib\site-packages\scrapy\utils\defer.py", line 169, in maybeDeferred_coro
    result = f(*args, **kw)
  File "c:\users\mingbotian\appdata\local\programs\python\python37-32\lib\site-packages\pydispatch\robustapply.py", line 55, in robustApply
    return receiver(*arguments, **named)
  File "c:\users\mingbo~1\appdata\local\temp\4\tutorial-1653404043-kum8t2lx.egg\tutorial\extensions.py", line 31, in item_scraped
  File "c:\users\mingbotian\appdata\local\programs\python\python37-32\lib\site-packages\requests\api.py", line 119, in post
    return request('post', url, data=data, json=json, **kwargs)
  File "c:\users\mingbotian\appdata\local\programs\python\python37-32\lib\site-packages\requests\api.py", line 61, in request
    return session.request(method=method, url=url, **kwargs)
  File "c:\users\mingbotian\appdata\local\programs\python\python37-32\lib\site-packages\requests\sessions.py", line 542, in request
    resp = self.send(prep, **send_kwargs)
  File "c:\users\mingbotian\appdata\local\programs\python\python37-32\lib\site-packages\requests\sessions.py", line 655, in send
    r = adapter.send(request, **kwargs)
  File "c:\users\mingbotian\appdata\local\programs\python\python37-32\lib\site-packages\requests\adapters.py", line 516, in send
    raise ConnectionError(e, request=request)
requests.exceptions.ConnectionError: HTTPConnectionPool(host='localhost', port=5000): Max retries exceeded with url: /notify (Caused by NewConnectionError('<urllib3.connection.HTTPConnection object at 0x06585290>: Failed to establish a new connection: [WinError 10061] 由于目标计算机积极拒绝，无法连接。'))
2022-05-24 22:55:16 [scrapy.core.scraper] DEBUG: Scraped from <200 http://quotes.toscrape.com/>
{'author': 'Eleanor Roosevelt',
 'tags': ['misattributed-eleanor-roosevelt'],
 'text': '“A woman is like a tea bag; you never know how str...'}
2022-05-24 22:55:16 [urllib3.connectionpool] DEBUG: Starting new HTTP connection (1): localhost:5000
2022-05-24 22:55:20 [scrapy.utils.signal] ERROR: Error caught on signal handler: <bound method NotificationException.item_scraped of <tutorial.extensions.NotificationException object at 0x059977D0>>
Traceback (most recent call last):
  File "c:\users\mingbotian\appdata\local\programs\python\python37-32\lib\site-packages\urllib3\connection.py", line 175, in _new_conn
    (self._dns_host, self.port), self.timeout, **extra_kw
  File "c:\users\mingbotian\appdata\local\programs\python\python37-32\lib\site-packages\urllib3\util\connection.py", line 95, in create_connection
    raise err
  File "c:\users\mingbotian\appdata\local\programs\python\python37-32\lib\site-packages\urllib3\util\connection.py", line 85, in create_connection
    sock.connect(sa)
ConnectionRefusedError: [WinError 10061] 由于目标计算机积极拒绝，无法连接。

During handling of the above exception, another exception occurred:

Traceback (most recent call last):
  File "c:\users\mingbotian\appdata\local\programs\python\python37-32\lib\site-packages\urllib3\connectionpool.py", line 710, in urlopen
    chunked=chunked,
  File "c:\users\mingbotian\appdata\local\programs\python\python37-32\lib\site-packages\urllib3\connectionpool.py", line 398, in _make_request
    conn.request(method, url, **httplib_request_kw)
  File "c:\users\mingbotian\appdata\local\programs\python\python37-32\lib\site-packages\urllib3\connection.py", line 239, in request
    super(HTTPConnection, self).request(method, url, body=body, headers=headers)
  File "c:\users\mingbotian\appdata\local\programs\python\python37-32\lib\http\client.py", line 1229, in request
    self._send_request(method, url, body, headers, encode_chunked)
  File "c:\users\mingbotian\appdata\local\programs\python\python37-32\lib\http\client.py", line 1275, in _send_request
    self.endheaders(body, encode_chunked=encode_chunked)
  File "c:\users\mingbotian\appdata\local\programs\python\python37-32\lib\http\client.py", line 1224, in endheaders
    self._send_output(message_body, encode_chunked=encode_chunked)
  File "c:\users\mingbotian\appdata\local\programs\python\python37-32\lib\http\client.py", line 1016, in _send_output
    self.send(msg)
  File "c:\users\mingbotian\appdata\local\programs\python\python37-32\lib\http\client.py", line 956, in send
    self.connect()
  File "c:\users\mingbotian\appdata\local\programs\python\python37-32\lib\site-packages\urllib3\connection.py", line 205, in connect
    conn = self._new_conn()
  File "c:\users\mingbotian\appdata\local\programs\python\python37-32\lib\site-packages\urllib3\connection.py", line 187, in _new_conn
    self, "Failed to establish a new connection: %s" % e
urllib3.exceptions.NewConnectionError: <urllib3.connection.HTTPConnection object at 0x060EC7F0>: Failed to establish a new connection: [WinError 10061] 由于目标计算机积极拒绝，无法连接。

During handling of the above exception, another exception occurred:

Traceback (most recent call last):
  File "c:\users\mingbotian\appdata\local\programs\python\python37-32\lib\site-packages\requests\adapters.py", line 449, in send
    timeout=timeout
  File "c:\users\mingbotian\appdata\local\programs\python\python37-32\lib\site-packages\urllib3\connectionpool.py", line 786, in urlopen
    method, url, error=e, _pool=self, _stacktrace=sys.exc_info()[2]
  File "c:\users\mingbotian\appdata\local\programs\python\python37-32\lib\site-packages\urllib3\util\retry.py", line 592, in increment
    raise MaxRetryError(_pool, url, error or ResponseError(cause))
urllib3.exceptions.MaxRetryError: HTTPConnectionPool(host='localhost', port=5000): Max retries exceeded with url: /notify (Caused by NewConnectionError('<urllib3.connection.HTTPConnection object at 0x060EC7F0>: Failed to establish a new connection: [WinError 10061] 由于目标计算机积极拒绝，无法连接。'))

During handling of the above exception, another exception occurred:

Traceback (most recent call last):
  File "c:\users\mingbotian\appdata\local\programs\python\python37-32\lib\site-packages\scrapy\utils\defer.py", line 169, in maybeDeferred_coro
    result = f(*args, **kw)
  File "c:\users\mingbotian\appdata\local\programs\python\python37-32\lib\site-packages\pydispatch\robustapply.py", line 55, in robustApply
    return receiver(*arguments, **named)
  File "c:\users\mingbo~1\appdata\local\temp\4\tutorial-1653404043-kum8t2lx.egg\tutorial\extensions.py", line 31, in item_scraped
  File "c:\users\mingbotian\appdata\local\programs\python\python37-32\lib\site-packages\requests\api.py", line 119, in post
    return request('post', url, data=data, json=json, **kwargs)
  File "c:\users\mingbotian\appdata\local\programs\python\python37-32\lib\site-packages\requests\api.py", line 61, in request
    return session.request(method=method, url=url, **kwargs)
  File "c:\users\mingbotian\appdata\local\programs\python\python37-32\lib\site-packages\requests\sessions.py", line 542, in request
    resp = self.send(prep, **send_kwargs)
  File "c:\users\mingbotian\appdata\local\programs\python\python37-32\lib\site-packages\requests\sessions.py", line 655, in send
    r = adapter.send(request, **kwargs)
  File "c:\users\mingbotian\appdata\local\programs\python\python37-32\lib\site-packages\requests\adapters.py", line 516, in send
    raise ConnectionError(e, request=request)
requests.exceptions.ConnectionError: HTTPConnectionPool(host='localhost', port=5000): Max retries exceeded with url: /notify (Caused by NewConnectionError('<urllib3.connection.HTTPConnection object at 0x060EC7F0>: Failed to establish a new connection: [WinError 10061] 由于目标计算机积极拒绝，无法连接。'))
2022-05-24 22:55:20 [scrapy.core.scraper] DEBUG: Scraped from <200 http://quotes.toscrape.com/>
{'author': 'Steve Martin',
 'tags': ['humor', 'obvious', 'simile'],
 'text': '“A day without sunshine is like, you know, night.”'}
2022-05-24 22:55:20 [urllib3.connectionpool] DEBUG: Starting new HTTP connection (1): localhost:5000
2022-05-24 22:55:24 [scrapy.utils.signal] ERROR: Error caught on signal handler: <bound method NotificationException.item_scraped of <tutorial.extensions.NotificationException object at 0x059977D0>>
Traceback (most recent call last):
  File "c:\users\mingbotian\appdata\local\programs\python\python37-32\lib\site-packages\urllib3\connection.py", line 175, in _new_conn
    (self._dns_host, self.port), self.timeout, **extra_kw
  File "c:\users\mingbotian\appdata\local\programs\python\python37-32\lib\site-packages\urllib3\util\connection.py", line 95, in create_connection
    raise err
  File "c:\users\mingbotian\appdata\local\programs\python\python37-32\lib\site-packages\urllib3\util\connection.py", line 85, in create_connection
    sock.connect(sa)
ConnectionRefusedError: [WinError 10061] 由于目标计算机积极拒绝，无法连接。

During handling of the above exception, another exception occurred:

Traceback (most recent call last):
  File "c:\users\mingbotian\appdata\local\programs\python\python37-32\lib\site-packages\urllib3\connectionpool.py", line 710, in urlopen
    chunked=chunked,
  File "c:\users\mingbotian\appdata\local\programs\python\python37-32\lib\site-packages\urllib3\connectionpool.py", line 398, in _make_request
    conn.request(method, url, **httplib_request_kw)
  File "c:\users\mingbotian\appdata\local\programs\python\python37-32\lib\site-packages\urllib3\connection.py", line 239, in request
    super(HTTPConnection, self).request(method, url, body=body, headers=headers)
  File "c:\users\mingbotian\appdata\local\programs\python\python37-32\lib\http\client.py", line 1229, in request
    self._send_request(method, url, body, headers, encode_chunked)
  File "c:\users\mingbotian\appdata\local\programs\python\python37-32\lib\http\client.py", line 1275, in _send_request
    self.endheaders(body, encode_chunked=encode_chunked)
  File "c:\users\mingbotian\appdata\local\programs\python\python37-32\lib\http\client.py", line 1224, in endheaders
    self._send_output(message_body, encode_chunked=encode_chunked)
  File "c:\users\mingbotian\appdata\local\programs\python\python37-32\lib\http\client.py", line 1016, in _send_output
    self.send(msg)
  File "c:\users\mingbotian\appdata\local\programs\python\python37-32\lib\http\client.py", line 956, in send
    self.connect()
  File "c:\users\mingbotian\appdata\local\programs\python\python37-32\lib\site-packages\urllib3\connection.py", line 205, in connect
    conn = self._new_conn()
  File "c:\users\mingbotian\appdata\local\programs\python\python37-32\lib\site-packages\urllib3\connection.py", line 187, in _new_conn
    self, "Failed to establish a new connection: %s" % e
urllib3.exceptions.NewConnectionError: <urllib3.connection.HTTPConnection object at 0x060EC350>: Failed to establish a new connection: [WinError 10061] 由于目标计算机积极拒绝，无法连接。

During handling of the above exception, another exception occurred:

Traceback (most recent call last):
  File "c:\users\mingbotian\appdata\local\programs\python\python37-32\lib\site-packages\requests\adapters.py", line 449, in send
    timeout=timeout
  File "c:\users\mingbotian\appdata\local\programs\python\python37-32\lib\site-packages\urllib3\connectionpool.py", line 786, in urlopen
    method, url, error=e, _pool=self, _stacktrace=sys.exc_info()[2]
  File "c:\users\mingbotian\appdata\local\programs\python\python37-32\lib\site-packages\urllib3\util\retry.py", line 592, in increment
    raise MaxRetryError(_pool, url, error or ResponseError(cause))
urllib3.exceptions.MaxRetryError: HTTPConnectionPool(host='localhost', port=5000): Max retries exceeded with url: /notify (Caused by NewConnectionError('<urllib3.connection.HTTPConnection object at 0x060EC350>: Failed to establish a new connection: [WinError 10061] 由于目标计算机积极拒绝，无法连接。'))

During handling of the above exception, another exception occurred:

Traceback (most recent call last):
  File "c:\users\mingbotian\appdata\local\programs\python\python37-32\lib\site-packages\scrapy\utils\defer.py", line 169, in maybeDeferred_coro
    result = f(*args, **kw)
  File "c:\users\mingbotian\appdata\local\programs\python\python37-32\lib\site-packages\pydispatch\robustapply.py", line 55, in robustApply
    return receiver(*arguments, **named)
  File "c:\users\mingbo~1\appdata\local\temp\4\tutorial-1653404043-kum8t2lx.egg\tutorial\extensions.py", line 31, in item_scraped
  File "c:\users\mingbotian\appdata\local\programs\python\python37-32\lib\site-packages\requests\api.py", line 119, in post
    return request('post', url, data=data, json=json, **kwargs)
  File "c:\users\mingbotian\appdata\local\programs\python\python37-32\lib\site-packages\requests\api.py", line 61, in request
    return session.request(method=method, url=url, **kwargs)
  File "c:\users\mingbotian\appdata\local\programs\python\python37-32\lib\site-packages\requests\sessions.py", line 542, in request
    resp = self.send(prep, **send_kwargs)
  File "c:\users\mingbotian\appdata\local\programs\python\python37-32\lib\site-packages\requests\sessions.py", line 655, in send
    r = adapter.send(request, **kwargs)
  File "c:\users\mingbotian\appdata\local\programs\python\python37-32\lib\site-packages\requests\adapters.py", line 516, in send
    raise ConnectionError(e, request=request)
requests.exceptions.ConnectionError: HTTPConnectionPool(host='localhost', port=5000): Max retries exceeded with url: /notify (Caused by NewConnectionError('<urllib3.connection.HTTPConnection object at 0x060EC350>: Failed to establish a new connection: [WinError 10061] 由于目标计算机积极拒绝，无法连接。'))
2022-05-24 22:55:24 [scrapy.core.engine] DEBUG: Crawled (200) <GET http://quotes.toscrape.com/page/2/> (referer: http://quotes.toscrape.com/)
2022-05-24 22:55:24 [scrapy.core.scraper] DEBUG: Scraped from <200 http://quotes.toscrape.com/page/2/>
{'author': 'Marilyn Monroe',
 'tags': ['friends', 'heartbreak', 'inspirational', 'life', 'love', 'sisters'],
 'text': '“This life is what you make it. No matter what, yo...'}
2022-05-24 22:55:24 [urllib3.connectionpool] DEBUG: Starting new HTTP connection (1): localhost:5000
2022-05-24 22:55:29 [scrapy.utils.signal] ERROR: Error caught on signal handler: <bound method NotificationException.item_scraped of <tutorial.extensions.NotificationException object at 0x059977D0>>
Traceback (most recent call last):
  File "c:\users\mingbotian\appdata\local\programs\python\python37-32\lib\site-packages\urllib3\connection.py", line 175, in _new_conn
    (self._dns_host, self.port), self.timeout, **extra_kw
  File "c:\users\mingbotian\appdata\local\programs\python\python37-32\lib\site-packages\urllib3\util\connection.py", line 95, in create_connection
    raise err
  File "c:\users\mingbotian\appdata\local\programs\python\python37-32\lib\site-packages\urllib3\util\connection.py", line 85, in create_connection
    sock.connect(sa)
ConnectionRefusedError: [WinError 10061] 由于目标计算机积极拒绝，无法连接。

During handling of the above exception, another exception occurred:

Traceback (most recent call last):
  File "c:\users\mingbotian\appdata\local\programs\python\python37-32\lib\site-packages\urllib3\connectionpool.py", line 710, in urlopen
    chunked=chunked,
  File "c:\users\mingbotian\appdata\local\programs\python\python37-32\lib\site-packages\urllib3\connectionpool.py", line 398, in _make_request
    conn.request(method, url, **httplib_request_kw)
  File "c:\users\mingbotian\appdata\local\programs\python\python37-32\lib\site-packages\urllib3\connection.py", line 239, in request
    super(HTTPConnection, self).request(method, url, body=body, headers=headers)
  File "c:\users\mingbotian\appdata\local\programs\python\python37-32\lib\http\client.py", line 1229, in request
    self._send_request(method, url, body, headers, encode_chunked)
  File "c:\users\mingbotian\appdata\local\programs\python\python37-32\lib\http\client.py", line 1275, in _send_request
    self.endheaders(body, encode_chunked=encode_chunked)
  File "c:\users\mingbotian\appdata\local\programs\python\python37-32\lib\http\client.py", line 1224, in endheaders
    self._send_output(message_body, encode_chunked=encode_chunked)
  File "c:\users\mingbotian\appdata\local\programs\python\python37-32\lib\http\client.py", line 1016, in _send_output
    self.send(msg)
  File "c:\users\mingbotian\appdata\local\programs\python\python37-32\lib\http\client.py", line 956, in send
    self.connect()
  File "c:\users\mingbotian\appdata\local\programs\python\python37-32\lib\site-packages\urllib3\connection.py", line 205, in connect
    conn = self._new_conn()
  File "c:\users\mingbotian\appdata\local\programs\python\python37-32\lib\site-packages\urllib3\connection.py", line 187, in _new_conn
    self, "Failed to establish a new connection: %s" % e
urllib3.exceptions.NewConnectionError: <urllib3.connection.HTTPConnection object at 0x065855D0>: Failed to establish a new connection: [WinError 10061] 由于目标计算机积极拒绝，无法连接。

During handling of the above exception, another exception occurred:

Traceback (most recent call last):
  File "c:\users\mingbotian\appdata\local\programs\python\python37-32\lib\site-packages\requests\adapters.py", line 449, in send
    timeout=timeout
  File "c:\users\mingbotian\appdata\local\programs\python\python37-32\lib\site-packages\urllib3\connectionpool.py", line 786, in urlopen
    method, url, error=e, _pool=self, _stacktrace=sys.exc_info()[2]
  File "c:\users\mingbotian\appdata\local\programs\python\python37-32\lib\site-packages\urllib3\util\retry.py", line 592, in increment
    raise MaxRetryError(_pool, url, error or ResponseError(cause))
urllib3.exceptions.MaxRetryError: HTTPConnectionPool(host='localhost', port=5000): Max retries exceeded with url: /notify (Caused by NewConnectionError('<urllib3.connection.HTTPConnection object at 0x065855D0>: Failed to establish a new connection: [WinError 10061] 由于目标计算机积极拒绝，无法连接。'))

During handling of the above exception, another exception occurred:

Traceback (most recent call last):
  File "c:\users\mingbotian\appdata\local\programs\python\python37-32\lib\site-packages\scrapy\utils\defer.py", line 169, in maybeDeferred_coro
    result = f(*args, **kw)
  File "c:\users\mingbotian\appdata\local\programs\python\python37-32\lib\site-packages\pydispatch\robustapply.py", line 55, in robustApply
    return receiver(*arguments, **named)
  File "c:\users\mingbo~1\appdata\local\temp\4\tutorial-1653404043-kum8t2lx.egg\tutorial\extensions.py", line 31, in item_scraped
  File "c:\users\mingbotian\appdata\local\programs\python\python37-32\lib\site-packages\requests\api.py", line 119, in post
    return request('post', url, data=data, json=json, **kwargs)
  File "c:\users\mingbotian\appdata\local\programs\python\python37-32\lib\site-packages\requests\api.py", line 61, in request
    return session.request(method=method, url=url, **kwargs)
  File "c:\users\mingbotian\appdata\local\programs\python\python37-32\lib\site-packages\requests\sessions.py", line 542, in request
    resp = self.send(prep, **send_kwargs)
  File "c:\users\mingbotian\appdata\local\programs\python\python37-32\lib\site-packages\requests\sessions.py", line 655, in send
    r = adapter.send(request, **kwargs)
  File "c:\users\mingbotian\appdata\local\programs\python\python37-32\lib\site-packages\requests\adapters.py", line 516, in send
    raise ConnectionError(e, request=request)
requests.exceptions.ConnectionError: HTTPConnectionPool(host='localhost', port=5000): Max retries exceeded with url: /notify (Caused by NewConnectionError('<urllib3.connection.HTTPConnection object at 0x065855D0>: Failed to establish a new connection: [WinError 10061] 由于目标计算机积极拒绝，无法连接。'))
2022-05-24 22:55:29 [scrapy.core.scraper] DEBUG: Scraped from <200 http://quotes.toscrape.com/page/2/>
{'author': 'J.K. Rowling',
 'tags': ['courage', 'friends'],
 'text': '“It takes a great deal of bravery to stand up to o...'}
2022-05-24 22:55:29 [urllib3.connectionpool] DEBUG: Starting new HTTP connection (1): localhost:5000
